Workbook

Sheet C1P
H3: =SUM(D15:G15) -> 37909 | I3: =SUM(H15:K15) -> 38717
A5: Producto Interno Bruto (PIB) | CF5: =SUM(CF15:CI15) -> 63888.121
A7: Series encadenadas de volumen con año de referencia 2015 | I7: Índice
A8: Datos originales | I8: Tasa de crecimiento anual
A9: Miles de millones de pesos | I9: Tasa de crecimiento año corrido
A10: 2005 - 2025pr cuarto trimestre
H11: =SUM(D15:G15) -> 37909
A12: Clasificación Cuentas Nacionales | B12: Secciones CIIU Rev. 4 A.C. 12 agrupaciones | C12: Concepto | D12: 2005 | H12: 2006 | L12: 2007 | P12: 2008 | T12: 2009 | X12: 2010 | AB12: 2011 | AF12: 2012 | AJ12: 2013 | AN12: 2014 | AR12: 2015 | AV12: 2016 | AZ12: 2017 | BD12: 2018 | BH12: 2019 | BL12: 2020 | BP12: 2021 | BT12: 2022 | BX12: 2023 | BY12: 2023pr | CB12: 2024p | CC12: 2023pr | CF12: 2025pr | CG12: 2023pr
D13: I | E13: II | F13: III | G13: IV | H13: I | I13: II | J13: III | K13: IV | L13: I | M13: II | N13: III | O13: IV | P13: I | Q13: II | R13: III | S13: IV | T13: I | U13: II | V13: III | W13: IV | X13: I | Y13: II | Z13: III | AA13: IV | AB13: I | AC13: II | AD13: III | AE13: IV | AF13: I | AG13: II | AH13: III | AI13: IV | AJ13: I | AK13: II | AL13: III | AM13: IV | AN13: I | AO13: II | AP13: III | AQ13: IV | AR13: I | AS13: II | AT13: III | AU13: IV | AV13: I | AW13: II | AX13: III | AY13: IV | AZ13: I | BA13: II | BB13: III | BC13: IV | BD13: I | BE13: II | BF13: III | BG13: IV | BH13: I | BI13: II | BJ13: III | BK13: IV | BL13: I | BM13: II | BN13: III | BO13: IV | BP13: I | BQ13: II | BR13: III | BS13: IV | BT13: I | BU13: II | BV13: III | BW13: IV | BX13: I | BY13: II | BZ13: III | CA13: IV | CB13: I | CC13: II | CD13: III | CE13: IV | CF13: I | CG13: II | CH13: III | CI13: IV
B15: A | C15: Agricultura, ganadería, caza, silvicultura y pesca | D15: 8790.3092 | E15: 9235.9265 | F15: 10131.952 | G15: 9750.8127 | H15: 8923.1481 | I15: 9216.8047 | J15: 10502.225 | K15: 10074.822 | L15: 9277.8062 | M15: 9552.3759 | N15: 11016.705 | O15: 10392.113 | P15: 9494.4998 | Q15: 9574.5342 | R15: 10898.67 | S15: 9947.2955 | T15: 9201.6384 | U15: 9303.5289 | V15: 11099.46 | W15: 10217.373 | X15: 9170.0768 | Y15: 9530.0457 | Z15: 10815.285 | AA15: 10427.593 | AB15: 9793.664 | AC15: 9701.6391 | AD15: 10878.875 | AE15: 10331.822 | AF15: 9960.5478 | AG15: 10218.776 | AH15: 11143.14 | AI15: 10402.536 | AJ15: 10305.601 | AK15: 11359.853 | AL15: 11956.095 | AM15: 11213.45 | AN15: 11097.83 | AO15: 11269.929 | AP15: 12185.836 | AQ15: 11586.405 | AR15: 11447.884 | AS15: 11579.526 | AT15: 13022.909 | AU15: 12073.681 | AV15: 11376.929 | AW15: 11692.178 | AX15: 13220.071 | AY15: 13151.821 | AZ15: 12648.93 | BA15: 12427.807 | BB15: 14008.503 | BC15: 13112.759 | BD15: 12764.937 | BE15: 12913.669 | BF15: 14140.695 | BG15: 13210.699 | BH15: 12947.978 | BI15: 13064.055 | BJ15: 14642.832 | BK15: 13816.135 | BL15: 13676.434 | BM15: 12926.396 | BN15: 14751.586 | BO15: 14184.584 | BP15: 14227.403 | BQ15: 13762.484 | BR15: 15219.863 | BS15: 14758.251 | BT15: 14019.812 | BU15: 14052.89 | BV15: 15095.528 | BW15: 14273.771 | BX15: 14137.414 | BY15: 13847.922 | BZ15: 15306.853 | CA15: 15096.811 | CB15: 14544.976 | CC15: 14876.726 | CD15: 16622.435 | CE15: 15922.863 | CF15: 15468.067 | CG15: 15430.091 | CH15: 17134.602 | CI15: 15855.361
B16: B | C16: Explotación de minas y canteras | D16: 6592.3892 | E16: 6869.3947 | F16: 6834.0478 | G16: 7134.1683 | H16: 6865.1489 | I16: 6797.3004 | J16: 7082.3134 | K16: 7314.2373 | L16: 6722.2691 | M16: 6878.8022 | N16: 7124.0003 | O16: 7708.9284 | P16: 7463.2658 | Q16: 7589.8046 | R16: 7913.3793 | S16: 8134.5503 | T16: 8054.5977 | U16: 8417.0066 | V16: 8698.6562 | W16: 9488.7395 | X16: 9243.1811 | Y16: 9722.948 | Z16: 9487.7341 | AA16: 9973.1368 | AB16: 10169.974 | AC16: 10924.63 | AD16: 11205.7 | AE16: 11673.696 | AF16: 11328.974 | AG16: 11547.73 | AH16: 11437.228 | AI16: 12021.068 | AJ16: 11666.955 | AK16: 12100.884 | AL16: 12193.107 | AM16: 12833.054 | AN16: 12147.824 | AO16: 11648.281 | AP16: 11904.877 | AQ16: 12435.018 | AR16: 11822.424 | AS16: 11981.225 | AT16: 11604.12 | AU16: 12219.231 | AV16: 11686.431 | AW16: 11380.396 | AX16: 11476.119 | AY16: 11710.054 | AZ16: 10729.042 | BA16: 10852.107 | BB16: 10732.087 | BC16: 11278.764 | BD16: 10228.693 | BE16: 10506.302 | BF16: 10740.397 | BG16: 11392.607 | BH16: 10714.291 | BI16: 10558.258 | BJ16: 10773.46 | BK16: 11646.991 | BL16: 10372.59 | BM16: 8353.0282 | BN16: 8813.815 | BO16: 9516.5669 | BP16: 8916.1366 | BQ16: 8788.8475 | BR16: 9025.3914 | BS16: 10249.625 | BT16: 9106.7119 | BU16: 9076.7185 | BV16: 9664.3824 | BW16: 9670.1872 | BX16: 9404.7982 | BY16: 9382.9909 | BZ16: 9868.8485 | CA16: 9824.3624 | CB16: 9334.0928 | CC16: 9205.0128 | CD16: 9315.8093 | CE16: 9313.0851 | CF16: 8800.01 | CG16: 8260.8344 | CH16: 8764.5722 | CI16: 9042.8604
B17: C | C17: Industrias manufactureras | D17: 17589.141 | E17: 19231.589 | F17: 20020.828 | G17: 20410.442 | H17: 18696.145 | I17: 19896.254 | J17: 21916.025 | K17: 22376.576 | L17: 20585.558 | M17: 21585.35 | N17: 23114.862 | O17: 24034.23 | P17: 21455.898 | Q17: 22279.229 | R17: 23089.636 | S17: 22814.237 | T17: 20534.213 | U17: 20829.399 | V17: 22290.69 | W17: 22699.698 | X17: 20599.938 | Y17: 21568.781 | Z17: 22505.659 | AA17: 23305.622 | AB17: 21875.783 | AC17: 22592.285 | AD17: 24227.686 | AE17: 24200.245 | AF17: 22554.935 | AG17: 22856.841 | AH17: 24219.153 | AI17: 24036.071 | AJ17: 21586.527 | AK17: 23707.988 | AL17: 24754.432 | AM17: 25032.053 | AN17: 23069.198 | AO17: 23912.265 | AP17: 25352.407 | AQ17: 25495.13 | AR17: 23229.668 | AS17: 24148.232 | AT17: 25925.717 | AU17: 26485.382 | AV17: 24236.419 | AW17: 25602.738 | AX17: 26290.843 | AY17: 26876 | AZ17: 24391.063 | BA17: 24436.141 | BB17: 26003.398 | BC17: 26304.397 | BD17: 23834.359 | BE17: 25367.316 | BF17: 26513.098 | BG17: 26912.228 | BH17: 24377.308 | BI17: 25331.828 | BJ17: 26876.768 | BK17: 27274.095 | BL17: 24082.005 | BM17: 18387.012 | BN17: 24804.771 | BO17: 26980.211 | BP17: 25251.992 | BQ17: 24095.48 | BR17: 28505.911 | BS17: 29212.617 | BT17: 27301.263 | BU17: 28402.716 | BV17: 30101.686 | BW17: 29996.336 | BX17: 28122.632 | BY17: 27987.521 | BZ17: 28867.953 | CA17: 28946.894 | CB17: 26568.445 | CC17: 27416.931 | CD17: 28217.097 | CE17: 28800.528 | CF17: 26947.14 | CG17: 27631.096 | CH17: 29383.819 | CI17: 29094.506
B18: D + E | C18: Suministro de electricidad, gas, vapor y aire acondicionado; Distribución de agua; evacuación y tratamiento de aguas residuales, gestión de desechos y actividades de saneamiento ambiental | D18: 4569.4659 | E18: 4654.2027 | F18: 4723.8287 | G18: 4737.5027 | H18: 4806.4049 | I18: 4866.9413 | J18: 4954.7764 | K18: 5050.8773 | L18: 5116.3782 | M18: 5061.9166 | N18: 5125.0681 | O18: 5207.637 | P18: 5034.5067 | Q18: 5105.0712 | R18: 5200.1237 | S18: 5279.2984 | T18: 5058.2893 | U18: 5149.9549 | V18: 5358.795 | W18: 5545.9608 | X18: 5477.8293 | Y18: 5447.405 | Z18: 5517.4241 | AA18: 5492.3415 | AB18: 5611.66 | AC18: 5583.229 | AD18: 5701.7854 | AE18: 5711.3256 | AF18: 5734.2276 | AG18: 5709.7382 | AH18: 5841.8436 | AI18: 5808.1907 | AJ18: 5847.2276 | AK18: 5978.505 | AL18: 6062.4855 | AM18: 6061.7819 | AN18: 6109.9747 | AO18: 6198.7077 | AP18: 6289.244 | AQ18: 6175.0736 | AR18: 6069.884 | AS18: 6065.2999 | AT18: 6266.4382 | AU18: 6197.3779 | AV18: 6137.1828 | AW18: 6011.9198 | AX18: 6214.7722 | AY18: 6233.1252 | AZ18: 6168.4074 | BA18: 6200.6571 | BB18: 6462.2663 | BC18: 6475.6693 | BD18: 6294.5868 | BE18: 6370.4434 | BF18: 6655.0361 | BG18: 6631.9337 | BH18: 6491.7604 | BI18: 6540.1256 | BJ18: 6819.5981 | BK18: 6754.5158 | BL18: 6612.8675 | BM18: 5923.1188 | BN18: 6431.8586 | BO18: 6619.1551 | BP18: 6522.1206 | BQ18: 6483.7845 | BR18: 6987.0198 | BS18: 7086.0751 | BT18: 6904.8012 | BU18: 6973.4849 | BV18: 7205.5573 | BW18: 7243.1566 | BX18: 7069.128 | BY18: 7148.6124 | BZ18: 7473.9116 | CA18: 7529.348 | CB18: 7462.8136 | CC18: 7363.8831 | CD18: 7572.2763 | CE18: 7549.0271 | CF18: 7363.7066 | CG18: 7430.3135 | CH18: 7728.2987 | CI18: 7767.2836
B19: F | C19: Construcción | D19: 7664.2016 | E19: 6279.2183 | F19: 7076.3523 | G19: 8788.2278 | H19: 8116.8906 | I19: 6978.6757 | J19: 8327.2679 | K19: 10004.166 | L19: 8636.1703 | M19: 8330.4976 | N19: 8744.1252 | O19: 10036.207 | P19: 8762.6427 | Q19: 9786.3606 | R19: 10723.559 | S19: 10016.438 | T19: 8473.3176 | U19: 10614.757 | V19: 10347.871 | W19: 10880.054 | X19: 8909.8084 | Y19: 9646.8102 | Z19: 9941.597 | AA19: 11549.784 | AB19: 9096.0198 | AC19: 10513.935 | AD19: 11102.807 | AE19: 11823.238 | AF19: 10710.469 | AG19: 12076.412 | AH19: 10256.528 | AI19: 12007.59 | AJ19: 10894.653 | AK19: 12755.641 | AL19: 13063.174 | AM19: 13417.533 | AN19: 12469.589 | AO19: 13578.946 | AP19: 14398.541 | AQ19: 14154.924 | AR19: 13195.72 | AS19: 14903.054 | AT19: 14659.67 | AU19: 15283.556 | AV19: 14339.67 | AW19: 15286.252 | AX19: 15325.918 | AY19: 15173.16 | AZ19: 13715.937 | BA19: 15117.399 | BB19: 15003.007 | BC19: 15070.658 | BD19: 13571.103 | BE19: 14121.17 | BF19: 15326.309 | BG19: 15137.418 | BH19: 13598.259 | BI19: 13877.765 | BJ19: 14015.097 | BK19: 14401.879 | BL19: 11086.692 | BM19: 7838.7481 | BN19: 9796.7456 | BO19: 10636.814 | BP19: 10305.013 | BQ19: 9706.9536 | BR19: 9771.9111 | BS19: 11255.122 | BT19: 10827.442 | BU19: 10621.912 | BV19: 11169.294 | BW19: 11146.352 | BX19: 10630.611 | BY19: 10483.337 | BZ19: 10337.714 | CA19: 10960.339 | CB19: 10571.505 | CC19: 10494.32 | CD19: 10549.124 | CE19: 10833.051 | CF19: 10253.109 | CG19: 10119.096 | CH19: 10350.991 | CI19: 10549.857
B20: G + H + I | C20: Comercio al por mayor y al por menor; reparación de vehículos automotores y motocicletas; Transporte y almacenamiento; Alojamiento y servicios de comida | D20: 19640.391 | E20: 20946.162 | F20: 21324.236 | G20: 23516.211 | H20: 20786.839 | I20: 22218.285 | J20: 23316.259 | K20: 25604.617 | L20: 22680.962 | M20: 24012.078 | N20: 24969.726 | O20: 27680.234 | P20: 24083.328 | Q20: 24987.794 | R20: 25526.739 | S20: 27748.138 | T20: 23694.795 | U20: 24819.381 | V20: 25578.988 | W20: 28091.837 | X20: 24763.731 | Y20: 25986.494 | Z20: 26939.107 | AA20: 29957.668 | AB20: 26384.518 | AC20: 28029.435 | AD20: 28993.041 | AE20: 31656.006 | AF20: 28030.095 | AG20: 29187.252 | AH20: 29745.273 | AI20: 32490.38 | AJ20: 28781.369 | AK20: 30659.919 | AL20: 31290.788 | AM20: 34416.925 | AN20: 30361.573 | AO20: 31948.679 | AP20: 32734.375 | AQ20: 36018.373 | AR20: 31452.895 | AS20: 32855.095 | AT20: 33856.424 | AU20: 37264.586 | AV20: 32577.695 | AW20: 33669.427 | AX20: 34592.1 | AY20: 38226.779 | AZ20: 32976.282 | BA20: 34438.58 | BB20: 35788.653 | BC20: 38448.484 | BD20: 34235.812 | BE20: 35461.931 | BF20: 36420.056 | BG20: 39320.202 | BH20: 34982.89 | BI20: 36658.561 | BJ20: 38239.194 | BK20: 41009.355 | BL20: 36054.615 | BM20: 24740.586 | BN20: 30547.514 | BO20: 38892.285 | BP20: 35506.805 | BQ20: 34612.928 | BR20: 40031.075 | BS20: 46664.193 | BT20: 40847.977 | BU20: 42630.469 | BV20: 44588.873 | BW20: 47383.681 | BX20: 40482.128 | BY20: 40764.79 | BZ20: 41939.34 | CA20: 45880.742 | CB20: 40088.07 | CC20: 40740.826 | CD20: 42379.817 | CE20: 47942.286 | CF20: 41566.057 | CG20: 43106.4 | CH20: 44774.812 | CI20: 49574.508
B21: J | C21: Información y comunicaciones | D21: 2844.2886 | E21: 3064.9642 | F21: 2948.8702 | G21: 3871.877 | H21: 3373.8843 | I21: 3685.3631 | J21: 3482.4948 | K21: 4087.2579 | L21: 3792.7595 | M21: 3979.1224 | N21: 4361.3481 | O21: 4627.77 | P21: 4074.979 | Q21: 4182.6272 | R21: 4378.088 | S21: 4484.3057 | T21: 3842.6323 | U21: 3820.6827 | V21: 3713.0051 | W21: 4292.6799 | X21: 4063.0914 | Y21: 4461.016 | Z21: 4610.2349 | AA21: 5121.6577 | AB21: 4714.9302 | AC21: 4827.3913 | AD21: 5076.5355 | AE21: 5534.143 | AF21: 4855.8277 | AG21: 4875.427 | AH21: 4995.196 | AI21: 5688.5493 | AJ21: 5170.0999 | AK21: 5318.0308 | AL21: 5590.6069 | AM21: 6139.2624 | AN21: 5645.9837 | AO21: 5808.6139 | AP21: 5733.7076 | AQ21: 6465.6948 | AR21: 5667.8964 | AS21: 5762.5458 | AT21: 5972.0252 | AU21: 6558.5325 | AV21: 5686.9792 | AW21: 5811.0582 | AX21: 5921.5831 | AY21: 6384.3795 | AZ21: 5608.7036 | BA21: 5814.2199 | BB21: 5749.9205 | BC21: 6585.156 | BD21: 5651.2779 | BE21: 5971.2315 | BF21: 6146.0438 | BG21: 6826.4467 | BH21: 5839.0838 | BI21: 6136.1388 | BJ21: 6068.1294 | BK21: 6777.648 | BL21: 5873.0649 | BM21: 5773.356 | BN21: 5938.6877 | BO21: 6547.8914 | BP21: 6070.5757 | BQ21: 6453.3384 | BR21: 6784.3066 | BS21: 7901.7793 | BT21: 7335.7056 | BU21: 7528.2755 | BV21: 7644.5357 | BW21: 8055.4831 | BX21: 7515.6431 | BY21: 7597.515 | BZ21: 7557.3479 | CA21: 8363.494 | CB21: 7342.7285 | CC21: 7512.7271 | CD21: 7677.2645 | CE21: 8436.28 | CF21: 7375.3696 | CG21: 7731.4708 | CH21: 7823.9085 | CI21: 8338.2861
B22: K | C22: Actividades financieras y de seguros | D22: 3810.3818 | E22: 3800.1953 | F22: 3925.3989 | G22: 3888.024 | H22: 4202.7529 | I22: 3953.9212 | J22: 4048.895 | K22: 4234.4309 | L22: 4561.1293 | M22: 4599.9342 | N22: 4586.0106 | O22: 4954.9259 | P22: 5099.862 | Q22: 4877.9752 | R22: 5070.4059 | S22: 5549.7569 | T22: 5462.1108 | U22: 5157.4931 | V22: 5279.5132 | W22: 5415.8828 | X22: 5296.2107 | Y22: 5447.6775 | Z22: 5642.0479 | AA22: 5926.0639 | AB22: 6003.9846 | AC22: 6043.1246 | AD22: 6166.0615 | AE22: 6540.8292 | AF22: 6524.2746 | AG22: 6607.6521 | AH22: 6590.487 | AI22: 6903.5863 | AJ22: 7169.6678 | AK22: 7182.5977 | AL22: 7081.2146 | AM22: 7726.5199 | AN22: 7829.6591 | AO22: 7926.7305 | AP22: 8038.7947 | AQ22: 8343.8158 | AR22: 8693.2543 | AS22: 8621.381 | AT22: 8717.425 | AU22: 8663.9396 | AV22: 8891.1996 | AW22: 8745.9069 | AX22: 8923.4288 | AY22: 9165.4647 | AZ22: 9102.9347 | BA22: 9390.0797 | BB22: 9325.5308 | BC22: 9832.4547 | BD22: 9434.2971 | BE22: 9787.3618 | BF22: 9745.8787 | BG22: 10089.462 | BH22: 10069.694 | BI22: 10277.41 | BJ22: 10575.71 | BK22: 10582.186 | BL22: 10308.053 | BM22: 10402.776 | BN22: 10799.374 | BO22: 10922.796 | BP22: 10826.578 | BQ22: 10747.939 | BR22: 11041.781 | BS22: 11386.702 | BT22: 10486.922 | BU22: 11971.907 | BV22: 12091.992 | BW22: 12389.179 | BX22: 12989.231 | BY22: 12542.214 | BZ22: 12398.603 | CA22: 13204.951 | CB22: 12703.545 | CC22: 12815.961 | CD22: 13024.378 | CE22: 13140.116 | CF22: 13120.146 | CG22: 13175.098 | CH22: 13591.239 | CI22: 13225.859
B23: L | C23: Actividades inmobiliarias | D23: 12401.89 | E23: 12505.838 | F23: 12581.406 | G23: 12743.867 | H23: 12835.292 | I23: 12986.941 | J23: 13131.315 | K23: 13311.451 | L23: 13380.504 | M23: 13496.911 | N23: 13600.448 | O23: 13747.137 | P23: 13726.531 | Q23: 13859.252 | R23: 13986.592 | S23: 14158.625 | T23: 14228.179 | U23: 14385.003 | V23: 14523.249 | W23: 14729.569 | X23: 14779.178 | Y23: 14910.885 | Z23: 15046.183 | AA23: 15195.754 | AB23: 15205.731 | AC23: 15323.855 | AD23: 15453.995 | AE23: 15644.418 | AF23: 15666.453 | AG23: 15799.927 | AH23: 15962.479 | AI23: 16150.141 | AJ23: 16166.466 | AK23: 16322.597 | AL23: 16465.748 | AM23: 16670.19 | AN23: 16689.594 | AO23: 16818.508 | AP23: 16975.09 | AQ23: 17180.808 | AR23: 17186.368 | AS23: 17335.378 | AT23: 17504.971 | AU23: 17798.283 | AV23: 17772.654 | AW23: 17992.276 | AX23: 18139.395 | AY23: 18384.676 | AZ23: 18350.569 | BA23: 18499.075 | BB23: 18672.652 | BC23: 18972.703 | BD23: 18957.811 | BE23: 19225.038 | BF23: 19503.435 | BG23: 19762.716 | BH23: 19787.092 | BI23: 19945.321 | BJ23: 20054.546 | BK23: 20177.041 | BL23: 20178.06 | BM23: 20077.666 | BN23: 20327.08 | BO23: 20535.195 | BP23: 20564.352 | BQ23: 20725.468 | BR23: 20845.947 | BS23: 21007.233 | BT23: 21033.94 | BU23: 21154.666 | BV23: 21277.515 | BW23: 21376.88 | BX23: 21413.302 | BY23: 21535.002 | BZ23: 21650.711 | CA23: 21813.985 | CB23: 21859.527 | CC23: 22024.482 | CD23: 22130.745 | CE23: 22307.246 | CF23: 22294.963 | CG23: 22461.557 | CH23: 22586.541 | CI23: 22730.744
B24: M + N | C24: Actividades profesionales, científicas y técnicas; Actividades de servicios administrativos y de apoyo | D24: 8402.0467 | E24: 8655.4516 | F24: 8856.4296 | G24: 10143.072 | H24: 8999.3431 | I24: 9239.7882 | J24: 9514.4231 | K24: 10838.446 | L24: 9631.1004 | M24: 9851.5071 | N24: 10218.567 | O24: 11544.825 | P24: 10102.937 | Q24: 10245.351 | R24: 10523.532 | S24: 11928.18 | T24: 10374.737 | U24: 10640.268 | V24: 10829.496 | W24: 12153.5 | X24: 10612.298 | Y24: 10917.585 | Z24: 11144.774 | AA24: 12679.342 | AB24: 11223.772 | AC24: 11601.396 | AD24: 12023.357 | AE24: 13719.476 | AF24: 11913.935 | AG24: 12224.618 | AH24: 12503.465 | AI24: 14264.982 | AJ24: 12258.593 | AK24: 12779.855 | AL24: 13241.204 | AM24: 15313.348 | AN24: 13328.007 | AO24: 13817.407 | AP24: 14191.572 | AQ24: 16163.013 | AR24: 13599.603 | AS24: 13844.779 | AT24: 14336.372 | AU24: 15611.246 | AV24: 13178.921 | AW24: 13527.314 | AX24: 13825.219 | AY24: 15463.546 | AZ24: 13214.524 | BA24: 13763.548 | BB24: 14114.122 | BC24: 15717.807 | BD24: 13658.468 | BE24: 14355.241 | BF24: 14694.811 | BG24: 16357.48 | BH24: 14195.182 | BI24: 14941.176 | BJ24: 15230.074 | BK24: 16735.568 | BL24: 14365.937 | BM24: 13079.188 | BN24: 13982.755 | BO24: 16136.119 | BP24: 14521.193 | BQ24: 14945.735 | BR24: 15796.752 | BS24: 17903.32 | BT24: 15770.851 | BU24: 16887.861 | BV24: 16935.938 | BW24: 18537.35 | BX24: 16313.72 | BY24: 17130.495 | BZ24: 17115.185 | CA24: 18877.599 | CB24: 16246.072 | CC24: 17065.705 | CD24: 17030.614 | CE24: 18803.608 | CF24: 16435.695 | CG24: 17331.799 | CH24: 17229.349 | CI24: 19076.803
B25: O + P + Q | C25: Administración pública y defensa; planes de seguridad social de afiliación obligatoria; Educación; Actividades de atención de la salud humana y de servicios sociales | D25: 17323.157 | E25: 17123.79 | F25: 17441.522 | G25: 19293.531 | H25: 17962.104 | I25: 17682.049 | J25: 18320.527 | K25: 20504.321 | L25: 18578.296 | M25: 18342.234 | N25: 19172.742 | O25: 21420.728 | P25: 19293.585 | Q25: 19092.906 | R25: 19329.088 | S25: 21451.421 | T25: 19581.38 | U25: 19586.838 | V25: 20084.098 | W25: 22328.684 | X25: 20565.505 | Y25: 20464.51 | Z25: 20788.83 | AA25: 23543.155 | AB25: 21746.413 | AC25: 21509.709 | AD25: 21968.947 | AE25: 25039.931 | AF25: 22844.961 | AG25: 22690.911 | AH25: 23288.938 | AI25: 26458.19 | AJ25: 23741.823 | AK25: 24107.805 | AL25: 24673.471 | AM25: 28007.902 | AN25: 25318.739 | AO25: 25166.905 | AP25: 26129.321 | AQ25: 29793.035 | AR25: 26821.055 | AS25: 27080.491 | AT25: 28737.271 | AU25: 29438.183 | AV25: 27319 | AW25: 28326.971 | AX25: 28963.345 | AY25: 31588.685 | AZ25: 28195.339 | BA25: 29338.96 | BB25: 29880.42 | BC25: 32807.28 | BD25: 29321.273 | BE25: 30904.023 | BF25: 31330.751 | BG25: 34359.953 | BH25: 30720.95 | BI25: 32627.214 | BJ25: 33015.831 | BK25: 35969.006 | BL25: 31068.918 | BM25: 31821.613 | BN25: 32417.007 | BO25: 37434.462 | BP25: 33193.705 | BQ25: 35088.196 | BR25: 35833.306 | BS25: 39858.793 | BT25: 34337.153 | BU25: 37060.605 | BV25: 35441.405 | BW25: 38749.837 | BX25: 34488.205 | BY25: 38875.121 | BZ25: 38036.565 | CA25: 41372.109 | CB25: 36481.815 | CC25: 40564.422 | CD25: 38604.022 | CE25: 43329.741 | CF25: 37800.812 | CG25: 41235.697 | CH25: 41662.98 | CI25: 45416.907
B26: R + S + T | C26: Actividades artísticas, de entretenimiento y recreación y otras actividades de servicios; Actividades de los hogares individuales en calidad de empleadores; actividades no diferenciadas de los hogares individuales como productores de bienes y servicios para uso propio | D26: 3062.3467 | E26: 3086.6502 | F26: 3230.2451 | G26: 3396.758 | H26: 3227.5616 | I26: 3289.4725 | J26: 3396.6279 | K26: 3510.338 | L26: 3400.4915 | M26: 3434.68 | N26: 3535.0164 | O26: 3764.812 | P26: 3531.8089 | Q26: 3539.6989 | R26: 3662.2171 | S26: 3824.2751 | T26: 3580.6588 | U26: 3626.0585 | V26: 3733.475 | W26: 3956.8077 | X26: 3712.3652 | Y26: 3688.6975 | Z26: 3833.5657 | AA26: 4024.3716 | AB26: 3852.8437 | AC26: 3939.0594 | AD26: 4150.9522 | AE26: 4245.1448 | AF26: 3989.2292 | AG26: 3998.5042 | AH26: 4348.4977 | AI26: 4340.7688 | AJ26: 4190.118 | AK26: 4246.1099 | AL26: 4531.9183 | AM26: 4749.8539 | AN26: 4442.555 | AO26: 4293.2336 | AP26: 4651.0877 | AQ26: 4823.1236 | AR26: 4539.4797 | AS26: 4496.6079 | AT26: 4848.5142 | AU26: 5097.3982 | AV26: 4811.6792 | AW26: 4805.5432 | AX26: 5107.5146 | AY26: 5309.263 | AZ26: 4954.6159 | BA26: 4894.9117 | BB26: 5191.2952 | BC26: 5415.1772 | BD26: 4833.623 | BE26: 5006.4008 | BF26: 5309.3039 | BG26: 5775.6723 | BH26: 5431.1567 | BI26: 5766.8764 | BJ26: 6013.0322 | BK26: 6441.9347 | BL26: 5635.939 | BM26: 3809.3984 | BN26: 5345.5629 | BO26: 6074.0998 | BP26: 6168.9947 | BQ26: 6736.1924 | BR26: 7153.1327 | BS26: 7989.6802 | BT26: 8042.7311 | BU26: 8340.2724 | BV26: 8980.3246 | BW26: 10568.672 | BX26: 9260.1955 | BY26: 9452.4622 | BZ26: 9928.354 | CA26: 11019.988 | CB26: 9831.645 | CC26: 10481.125 | CD26: 11064.665 | CE26: 11532.565 | CF26: 11363.528 | CG26: 11290.01 | CH26: 11638.34 | CI26: 12863.459
A27: B.1b | C27: Valor agregado bruto | D27: 111789.94 | E27: 115152.44 | F27: 118810.66 | G27: 126941.96 | H27: 118008.18 | I27: 120449.4 | J27: 127605.65 | K27: 135926.77 | L27: 125486.91 | M27: 128480.24 | N27: 135324.7 | O27: 144364.16 | P27: 131462.23 | Q27: 134338.88 | R27: 139797.04 | S27: 144564.85 | T27: 131692.99 | U27: 135619.68 | V27: 141259.09 | W27: 149381.24 | X27: 136962.7 | Y27: 141727.64 | Z27: 146460.78 | AA27: 156981.87 | AB27: 145905.14 | AC27: 150842.53 | AD27: 157551.37 | AE27: 166352.96 | AF27: 154648.87 | AG27: 158182.84 | AH27: 161013.73 | AI27: 170730.55 | AJ27: 158395.23 | AK27: 166948.62 | AL27: 171561.32 | AM27: 181920.82 | AN27: 168936.11 | AO27: 172331.83 | AP27: 178821.9 | AQ27: 188641.16 | AR27: 173726.18 | AS27: 178673.6 | AT27: 185451.82 | AU27: 192691.39 | AV27: 178014.88 | AW27: 182852.11 | AX27: 188000.32 | AY27: 197666.69 | AZ27: 180127.58 | BA27: 185272.23 | BB27: 191235.85 | BC27: 200239.34 | BD27: 182983.72 | BE27: 190157.25 | BF27: 196700.65 | BG27: 206066.37 | BH27: 189395.25 | BI27: 195906.44 | BJ27: 202482.3 | BK27: 211930 | BL27: 189639.81 | BM27: 163258.88 | BN27: 183882.66 | BO27: 204587.65 | BP27: 192289.73 | BQ27: 192325.5 | BR27: 207382.42 | BS27: 225751.35 | BT27: 206170.42 | BU27: 214522.88 | BV27: 220414.01 | BW27: 229104.69 | BX27: 211695.28 | BY27: 215981.05 | BZ27: 220969.14 | CA27: 232186.53 | CB27: 212938.45 | CC27: 219935.49 | CD27: 224560.36 | CE27: 237495.7 | CF27: 218543.41 | CG27: 224497.67 | CH27: 232840.97 | CI27: 242850.38
A28: D.21-D.31 | C28: Impuestos menos subvenciones sobre los productos | D28: 9461.1759 | E28: 10489.427 | F28: 10524.587 | G28: 12049.81 | H28: 10898.716 | I28: 11818.069 | J28: 11590.958 | K28: 13319.257 | L28: 12039.845 | M28: 12851.973 | N28: 13302.309 | O28: 14618.873 | P28: 13141.885 | Q28: 13740.322 | R28: 13766.813 | S28: 14851.981 | T28: 13107.436 | U28: 13478.292 | V28: 13149.921 | W28: 14879.351 | X28: 13457.875 | Y28: 14277.474 | Z28: 14196.064 | AA28: 16074.587 | AB28: 14757.135 | AC28: 15763.246 | AD28: 15818.037 | AE28: 17662.581 | AF28: 15874.963 | AG28: 16496.007 | AH28: 16251.426 | AI28: 18250.604 | AJ28: 16181.034 | AK28: 17093.4 | AL28: 16774.014 | AM28: 19046.552 | AN28: 17153.629 | AO28: 18044.411 | AP28: 17784.418 | AQ28: 19916.543 | AR28: 17637.047 | AS28: 18187.96 | AT28: 18181.901 | AU28: 20142.092 | AV28: 17892.884 | AW28: 18186.892 | AX28: 18805.261 | AY28: 20069.963 | AZ28: 17867.662 | BA28: 18309.314 | BB28: 19059.824 | BC28: 20536.2 | BD28: 18283.141 | BE28: 19028.383 | BF28: 19656.676 | BG28: 21119.8 | BH28: 18867.206 | BI28: 19710.93 | BJ28: 20636.811 | BK28: 22274.053 | BL28: 19339.304 | BM28: 16331.817 | BN28: 18971.359 | BO28: 21847.52 | BP28: 19816.985 | BQ28: 20359.037 | BR28: 22551.372 | BS28: 25912.607 | BT28: 23203.517 | BU28: 24569.512 | BV28: 26617.005 | BW28: 28469.967 | BX28: 24117.599 | BY28: 24044.634 | BZ28: 24890.796 | CA28: 27220.972 | CB28: 23595.205 | CC28: 23899.489 | CD28: 25243.377 | CE28: 28036.93 | CF28: 24110.161 | CG28: 24491.472 | CH28: 25934.277 | CI28: 28731.272
A29: B.1b | C29: Producto Interno Bruto | D29: 121117.73 | E29: 125559.34 | F29: 129223.31 | G29: 138952.62 | H29: 128839.68 | I29: 132242.91 | J29: 139114.41 | K29: 149238 | L29: 137488.52 | M29: 141316.5 | N29: 148649.97 | O29: 159002.02 | P29: 144602.69 | Q29: 148078.93 | R29: 153584.53 | S29: 159446.84 | T29: 144812.49 | U29: 149108.6 | V29: 154402.16 | W29: 164292.74 | X29: 150431.72 | Y29: 156004.2 | Z29: 160651.52 | AA29: 173063.55 | AB29: 160659.88 | AC29: 166585.33 | AD29: 173372.36 | AE29: 184010.44 | AF29: 170516.61 | AG29: 174658.12 | AH29: 177268.45 | AI29: 188971.82 | AJ29: 174578.04 | AK29: 184043.02 | AL29: 188345.14 | AM29: 200972.79 | AN29: 186100.22 | AO29: 190347.09 | AP29: 196605.87 | AQ29: 208535.82 | AR29: 191363.28 | AS29: 196861.4 | AT29: 203635.77 | AU29: 212831.55 | AV29: 195907.74 | AW29: 201038.99 | AX29: 206805.58 | AY29: 217736.68 | AZ29: 198002.9 | BA29: 203591.84 | BB29: 210300.68 | BC29: 220760.57 | BD29: 201268.45 | BE29: 209187.55 | BF29: 216359.03 | BG29: 227192.98 | BH29: 208263.59 | BI29: 215620.27 | BJ29: 223124.46 | BK29: 234215.69 | BL29: 208984.37 | BM29: 179587.95 | BN29: 202864.17 | BO29: 226463.51 | BP29: 212118.51 | BQ29: 212672.15 | BR29: 229893.55 | BS29: 251558.79 | BT29: 229311 | BU29: 239013.85 | BV29: 246908.06 | BW29: 257422.1 | BX29: 235748.94 | BY29: 239983.68 | BZ29: 245804.91 | CA29: 259305.47 | CB29: 236500.46 | CC29: 243822.84 | CD29: 249751.85 | CE29: 265414.85 | CF29: 242632.98 | CG29: 248985.66 | CH29: 258737.57 | CI29: 271434.71
A31: Fuente: DANE, PIB_T
A32: prpreliminar
A33: pprovisional
A34: Actualizado el 16 de febrero de 2026
A39: Producto Interno Bruto (PIB)
A41: Tasa de crecimiento anual (%)
A42: Base 2015
A43: 2006 - 2025pr cuarto trimestre
A45: Clasificación Cuentas Nacionales | B45: Secciones CIIU Rev. 4 A.C. 12 agrupaciones | C45: Concepto | H45: 2006 | L45: 2007 | P45: 2008 | T45: 2009 | X45: 2010 | AB45: 2011 | AF45: 2012 | AJ45: 2013 | AN45: 2014 | AR45: 2015 | AV45: 2016 | AZ45: 2017 | BD45: 2018 | BH45: 2019 | BL45: 2020 | BP45: 2021 | BT45: 2022 | BX45: 2023 | BY45: 2023pr | CB45: 2024p | CC45: 2023pr | CF45: 2025pr | CG45: 2023pr
H46: I | I46: II | J46: III | K46: IV | L46: I | M46: II | N46: III | O46: IV | P46: I | Q46: II | R46: III | S46: IV | T46: I | U46: II | V46: III | W46: IV | X46: I | Y46: II | Z46: III | AA46: IV | AB46: I | AC46: II | AD46: III | AE46: IV | AF46: I | AG46: II | AH46: III | AI46: IV | AJ46: I | AK46: II | AL46: III | AM46: IV | AN46: I | AO46: II | AP46: III | AQ46: IV | AR46: I | AS46: II | AT46: III | AU46: IV | AV46: I | AW46: II | AX46: III | AY46: IV | AZ46: I | BA46: II | BB46: III | BC46: IV | BD46: I | BE46: II | BF46: III | BG46: IV | BH46: I | BI46: II | BJ46: III | BK46: IV | BL46: I | BM46: II | BN46: III | BO46: IV | BP46: I | BQ46: II | BR46: III | BS46: IV | BT46: I | BU46: II | BV46: III | BW46: IV | BX46: I | BY46: II | BZ46: III | CA46: IV | CB46: I | CC46: II | CD46: III | CE46: IV | CF46: I | CG46: II | CH46: III | CI46: IV
B48: A | C48: Agricultura, ganadería, caza, silvicultura y pesca | H48: 1.5111974 | I48: -0.20703641 | J48: 3.65451 | K48: 3.3228986 | L48: 3.9745853 | M48: 3.6408622 | N48: 4.8987757 | O48: 3.1493386 | P48: 2.3356123 | Q48: 0.23196598 | R48: -1.0714161 | S48: -4.2803336 | T48: -3.084537 | U48: -2.8304797 | V48: 1.8423266 | W48: 2.7150847 | X48: -0.34300037 | Y48: 2.4347402 | Z48: -2.560258 | AA48: 2.057473 | AB48: 6.8002401 | AC48: 1.8005525 | AD48: 0.58796269 | AE48: -0.91843394 | AF48: 1.7039971 | AG48: 5.3304103 | AH48: 2.4291601 | AI48: 0.6844271 | AJ48: 3.4642009 | AK48: 11.166476 | AL48: 7.2955695 | AM48: 7.7953485 | AN48: 7.6873635 | AO48: -0.79159647 | AP48: 1.9215319 | AQ48: 3.3259613 | AR48: 3.1542569 | AS48: 2.7471012 | AT48: 6.8692315 | AU48: 4.2055867 | AV48: -0.61981064 | AW48: 0.97285977 | AX48: 1.5139667 | AY48: 8.9296722 | AZ48: 11.180531 | BA48: 6.2916322 | BB48: 5.9639012 | BC48: -0.29700746 | BD48: 0.91712616 | BE48: 3.9094741 | BF48: 0.94365531 | BG48: 0.74690207 | BH48: 1.4339385 | BI48: 1.1645482 | BJ48: 3.5510067 | BK48: 4.5829196 | BL48: 5.626021 | BM48: -1.053723 | BN48: 0.74270785 | BO48: 2.666806 | BP48: 4.0286004 | BQ48: 6.4680648 | BR48: 3.1744183 | BS48: 4.044295 | BT48: -1.4590949 | BU48: 2.1101292 | BV48: -0.81692761 | BW48: -3.2827712 | BX48: 0.83882936 | BY48: -1.4585479 | BZ48: 1.3999223 | CA48: 5.7661018 | CB48: 2.8828639 | CC48: 7.4293046 | CD48: 8.5947228 | CE48: 5.4716966 | CF48: 6.3464589 | CG48: 3.7196677 | CH48: 3.0811817 | CI48: -0.42393249
B49: B | C49: Explotación de minas y canteras | H49: 4.1374937 | I49: -1.0495008 | J49: 3.6327764 | K49: 2.5240362 | L49: -2.0812333 | M49: 1.199032 | N49: 0.58860499 | O49: 5.3962032 | P49: 11.023014 | Q49: 10.336137 | R49: 11.080558 | S49: 5.5211554 | T49: 7.9232326 | U49: 10.898858 | V49: 9.9234079 | W49: 16.647376 | X49: 14.756583 | Y49: 15.515508 | Z49: 9.0712623 | AA49: 5.10497 | AB49: 10.026771 | AC49: 12.359237 | AD49: 18.107231 | AE49: 17.051398 | AF49: 11.396295 | AG49: 5.7036252 | AH49: 2.0661622 | AI49: 2.9756802 | AJ49: 2.9833365 | AK49: 4.7901494 | AL49: 6.6089359 | AM49: 6.754691 | AN49: 4.1216319 | AO49: -3.7402478 | AP49: -2.3638789 | AQ49: -3.1016439 | AR49: -2.6786693 | AS49: 2.8583168 | AT49: -2.5263357 | AU49: -1.7353217 | AV49: -1.1503003 | AW49: -5.0147535 | AX49: -1.1030635 | AY49: -4.1670126 | AZ49: -8.1923138 | BA49: -4.6420994 | BB49: -6.4833042 | BC49: -3.6830737 | BD49: -4.6634958 | BE49: -3.1865238 | BF49: 0.077433358 | BG49: 1.0093585 | BH49: 4.7474036 | BI49: 0.49452468 | BJ49: 0.30783126 | BK49: 2.2328874 | BL49: -3.1892062 | BM49: -20.886307 | BN49: -18.189558 | BO49: -18.291628 | BP49: -14.041367 | BQ49: 5.2175005 | BR49: 2.4005088 | BS49: 7.7029638 | BT49: 2.1374201 | BU49: 3.2754125 | BV49: 7.0799258 | BW49: -5.6532541 | BX49: 3.2732596 | BY49: 3.3742635 | BZ49: 2.1156669 | CA49: 1.5943346 | CB49: -0.75180085 | CC49: -1.8968161 | CD49: -5.6038883 | CE49: -5.2041781 | CF49: -5.7218505 | CG49: -10.25722 | CH49: -5.9172214 | CI49: -2.9015589
B50: C | C50: Industrias manufactureras | H50: 6.2936781 | I50: 3.4561099 | J50: 9.4661283 | K50: 9.6329809 | L50: 10.105894 | M50: 8.4895195 | N50: 5.4701375 | O50: 7.4079891 | P50: 4.2279149 | Q50: 3.2145844 | R50: -0.10913065 | S50: -5.0760675 | T50: -4.2957179 | U50: -6.5075434 | V50: -3.4601933 | W50: -0.50204878 | X50: 0.32007523 | Y50: 3.549703 | Z50: 0.96438877 | AA50: 2.6693058 | AB50: 6.1934431 | AC50: 4.745306 | AD50: 7.6515293 | AE50: 3.8386567 | AF50: 3.1045826 | AG50: 1.1710007 | AH50: -0.03522096 | AI50: -0.67839956 | AJ50: -4.2935532 | AK50: 3.7238177 | AL50: 2.2101462 | AM50: 4.1436986 | AN50: 6.8685047 | AO50: 0.86163723 | AP50: 2.4156264 | AQ50: 1.8499359 | AR50: 0.69560251 | AS50: 0.98680543 | AT50: 2.2613669 | AU50: 3.8840814 | AV50: 4.3339018 | AW50: 6.0232363 | AX50: 1.4083519 | AY50: 1.4748458 | AZ50: 0.63806316 | BA50: -4.556529 | BB50: -1.0933261 | BC50: -2.1268152 | BD50: -2.2824114 | BE50: 3.8106462 | BF50: 1.9601262 | BG50: 2.3107546 | BH50: 2.2780126 | BI50: -0.13989596 | BJ50: 1.3716648 | BK50: 1.3446206 | BL50: -1.2113841 | BM50: -27.415376 | BN50: -7.7092496 | BO50: -1.0775201 | BP50: 4.8583415 | BQ50: 31.046195 | BR50: 14.92108 | BS50: 8.2742365 | BT50: 8.1152849 | BU50: 17.8757 | BV50: 5.5980488 | BW50: 2.6828079 | BX50: 3.0085414 | BY50: -1.461815 | BZ50: -4.0985517 | CA50: -3.4985656 | CB50: -5.5264666 | CC50: -2.0387297 | CD50: -2.254597 | CE50: -0.50563703 | CF50: 1.4253568 | CG50: 0.78114362 | CH50: 4.1348084 | CI50: 1.0207392
B51: D + E | C51: Suministro de electricidad, gas, vapor y aire acondicionado; Distribución de agua; evacuación y tratamiento de aguas residuales, gestión de desechos y actividades de saneamiento ambiental | H51: 5.185267 | I51: 4.5708935 | J51: 4.8889951 | K51: 6.6147634 | L51: 6.4491727 | M51: 4.0061157 | N51: 3.4369189 | O51: 3.1036132 | P51: -1.6001848 | Q51: 0.85253291 | R51: 1.4644805 | S51: 1.3760824 | T51: 0.47239073 | U51: 0.8792002 | V51: 3.0512985 | W51: 5.0510947 | X51: 8.2941089 | Y51: 5.7757799 | Z51: 2.9601644 | AA51: -0.96681583 | AB51: 2.4431337 | AC51: 2.4933697 | AD51: 3.341438 | AE51: 3.9870801 | AF51: 2.1841586 | AG51: 2.2658802 | AH51: 2.4563905 | AI51: 1.6960169 | AJ51: 1.9706243 | AK51: 4.7071646 | AL51: 3.776923 | AM51: 4.3660965 | AN51: 4.4935317 | AO51: 3.6832399 | AP51: 3.7403555 | AQ51: 1.8689518 | AR51: -0.65615047 | AS51: -2.1521869 | AT51: -0.36261622 | AU51: 0.36119766 | AV51: 1.1087325 | AW51: -0.88008976 | AX51: -0.82448732 | AY51: 0.57681318 | AZ51: 0.50877746 | BA51: 3.1393835 | BB51: 3.9823514 | BC51: 3.891212 | BD51: 2.0455755 | BE51: 2.738199 | BF51: 2.983006 | BG51: 2.4131012 | BH51: 3.1324312 | BI51: 2.6635852 | BJ51: 2.4727452 | BK51: 1.8483618 | BL51: 1.8655506 | BM51: -9.434173 | BN51: -5.6856657 | BO51: -2.004004 | BP51: -1.3722776 | BQ51: 9.4657173 | BR51: 8.6314275 | BS51: 7.0540726 | BT51: 5.8674252 | BU51: 7.5526942 | BV51: 3.127764 | BW51: 2.2167638 | BX51: 2.3798917 | BY51: 2.5113337 | BZ51: 3.7242688 | CA51: 3.9511973 | CB51: 5.5690833 | CC51: 3.011363 | CD51: 1.3161067 | CE51: 0.26136467 | CF51: -1.3280109 | CG51: 0.902112 | CH51: 2.060443 | CI51: 2.8911871
B52: F | C52: Construcción | H52: 5.9065393 | I52: 11.139242 | J52: 17.677406 | K52: 13.835987 | L52: 6.3975191 | M52: 19.370751 | N52: 5.0059316 | O52: 0.32027772 | P52: 1.4644507 | Q52: 17.476303 | R52: 22.6373 | S52: -0.19697997 | T52: -3.3018022 | U52: 8.4648077 | V52: -3.5033849 | W52: 8.6219882 | X52: 5.1513572 | Y52: -9.1188798 | Z52: -3.9261652 | AA52: 6.1555819 | AB52: 2.0899596 | AC52: 8.9887192 | AD52: 11.680316 | AE52: 2.3676114 | AF52: 17.748966 | AG52: 14.861016 | AH52: -7.6222076 | AI52: 1.5592345 | AJ52: 1.7196591 | AK52: 5.6244203 | AL52: 27.364483 | AM52: 11.742093 | AN52: 14.456045 | AO52: 6.4544434 | AP52: 10.222384 | AQ52: 5.4957255 | AR52: 5.8232148 | AS52: 9.751185 | AT52: 1.8135789 | AU52: 7.9734234 | AV52: 8.6691029 | AW52: 2.5712686 | AX52: 4.5447654 | AY52: -0.72231693 | AZ52: -4.3497052 | BA52: -1.1046101 | BB52: -2.1069632 | BC52: -0.67554608 | BD52: -1.0559548 | BE52: -6.5899482 | BF52: 2.1549209 | BG52: 0.44297933 | BH52: 0.20010138 | BI52: -1.7236849 | BJ52: -8.5553016 | BK52: -4.8590816 | BL52: -18.469766 | BM52: -43.515775 | BN52: -30.098626 | BO52: -26.14287 | BP52: -7.0506074 | BQ52: 23.832957 | BR52: -0.25349761 | BS52: 5.8129074 | BT52: 5.0696598 | BU52: 9.4258027 | BV52: 14.299997 | BW52: -0.96640829 | BX52: -1.8178933 | BY52: -1.3046156 | BZ52: -7.4452357 | CA52: -1.6688264 | CB52: -0.55599651 | CC52: 0.1047684 | CD52: 2.0450372 | CE52: -1.1613464 | CF52: -3.0118312 | CG52: -3.5754957 | CH52: -1.8781897 | CI52: -2.6141715
B53: G + H + I | C53: Comercio al por mayor y al por menor; reparación de vehículos automotores y motocicletas; Transporte y almacenamiento; Alojamiento y servicios de comida | H53: 5.8371951 | I53: 6.0733004 | J53: 9.3415923 | K53: 8.8807059 | L53: 9.1121239 | M53: 8.0734984 | N53: 7.0914752 | O53: 8.1064202 | P53: 6.1830129 | Q53: 4.0634389 | R53: 2.2307543 | S53: 0.24531541 | T53: -1.6132897 | U53: -0.67398265 | V53: 0.20468102 | W53: 1.2386376 | X53: 4.5112692 | Y53: 4.7024274 | Z53: 5.3173304 | AA53: 6.6418988 | AB53: 6.5450059 | AC53: 7.8615484 | AD53: 7.6243582 | AE53: 5.6691247 | AF53: 6.2369019 | AG53: 4.130719 | AH53: 2.5945274 | AI53: 2.6357524 | AJ53: 2.6802401 | AK53: 5.0455811 | AL53: 5.1958329 | AM53: 5.9295859 | AN53: 5.4903742 | AO53: 4.2034041 | AP53: 4.6134556 | AQ53: 4.6530836 | AR53: 3.5944178 | AS53: 2.8371018 | AT53: 3.4277391 | AU53: 3.4599361 | AV53: 3.5761409 | AW53: 2.4785536 | AX53: 2.1729297 | AY53: 2.5820566 | AZ53: 1.2234979 | BA53: 2.2844285 | BB53: 3.4590375 | BC53: 0.57997278 | BD53: 3.8195004 | BE53: 2.9715224 | BF53: 1.7642538 | BG53: 2.2672361 | BH53: 2.1821549 | BI53: 3.3744091 | BJ53: 4.9948784 | BK53: 4.2958921 | BL53: 3.0635694 | BM53: -32.510755 | BN53: -20.11465 | BO53: -5.1624079 | BP53: -1.5193909 | BQ53: 39.903427 | BR53: 31.045279 | BS53: 19.983161 | BT53: 15.042673 | BU53: 23.163429 | BV53: 11.38565 | BW53: 1.5418425 | BX53: -0.89563649 | BY53: -4.3763984 | BZ53: -5.9421385 | CA53: -3.1718491 | CB53: -0.97341137 | CC53: -0.058785282 | CD53: 1.0502718 | CE53: 4.4932671 | CF53: 3.68685 | CG53: 5.8063964 | CH53: 5.6512625 | CI53: 3.4045555
...

Sheet PIB oferta anual NORMAL
A1: Suma Agregada PIB por Oferta Anual
X3: PROYECCIÓN OFERTA ANUAL
A5: Secciones CIIU Rev. 4 A.C. 12 agrupaciones | B5: Concepto | C5: 2005 | D5: 2006 | E5: 2007 | F5: 2008 | G5: 2009 | H5: 2010 | I5: 2011 | J5: 2012 | K5: 2013 | L5: 2014 | M5: 2015 | N5: 2016 | O5: 2017 | P5: 2018 | Q5: 2019 | R5: 2020 | S5: 2021 | T5: 2022 | U5: 2023 | V5: 2024 | W5: 2025 | X5: 2026 | Y5: 2027 | Z5: 2028 | AA5: 2029 | AB5: 2030
A6: A | B6: Agricultura, ganadería, caza, silvicultura y pesca | C6: 37909 | D6: 38717 | E6: 40239 | F6: 39915 | G6: 39822 | H6: 39943 | I6: 40706 | J6: 41725 | K6: 44835 | L6: 46140 | M6: 48124 | N6: 49441 | O6: 52198 | P6: 53030 | Q6: 54471 | R6: 55539 | S6: 57968 | T6: 57442 | U6: 58389 | V6: 61967 | W6: 63888.121 | X6: =W6*(1+$X$20) -> 65216.919 | Y6: =X6*(1+$Y$20) -> 66778.492 | Z6: =Y6*(1+$Z$20) -> 68272.431 | AA6: =Z6*(1+$AA$20) -> 69853.479 | AB6: =AA6*(1+$AB$20) -> 71443.675
A7: B | B7: Explotación de minas y canteras | C7: 27430 | D7: 28059 | E7: 28434 | F7: 31101 | G7: 34659 | H7: 38427 | I7: 43974 | J7: 46335 | K7: 48794 | L7: 48136 | M7: 47627 | N7: 46253 | O7: 43592 | P7: 42868 | Q7: 43693 | R7: 37056 | S7: 36980 | T7: 37518 | U7: 38481 | V7: 37168 | W7: 34868.277 | X7: =35593.4966263493 -> 35593.497 | Y7: =X7*(1+$Y$20) -> 36445.757 | Z7: =Y7*(1+$Z$20) -> 37261.106 | AA7: =Z7*(1+$AA$20) -> 38123.996 | AB7: =AA7*(1+$AB$20) -> 38991.879
A8: C | B8: Industrias manufactureras | C8: 77252 | D8: 82885 | E8: 89320 | F8: 89639 | G8: 86354 | H8: 87980 | I8: 92896 | J8: 93667 | K8: 95081 | L8: 97829 | M8: 99789 | N8: 103006 | O8: 101135 | P8: 102627 | Q8: 103860 | R8: 94254 | S8: 107066 | T8: 115802 | U8: 113925 | V8: 111003 | W8: 113056.56 | X8: =W8*(1+$X$20) -> 115408.01 | Y8: =X8*(1+$Y$20) -> 118171.37 | Z8: =Y8*(1+$Z$20) -> 120815.05 | AA8: =Z8*(1+$AA$20) -> 123612.87 | AB8: =AA8*(1+$AB$20) -> 126426.89
A9: D + E | B9: Suministro de electricidad, gas, vapor y aire acondicionado; Distribución de agua; evacuación y tratamiento de aguas residuales, gestión de desechos y actividades de saneamiento ambiental | C9: 18685 | D9: 19679 | E9: 20511 | F9: 20619 | G9: 21113 | H9: 21935 | I9: 22608 | J9: 23094 | K9: 23950 | L9: 24773 | M9: 24599 | N9: 24597 | O9: 25307 | P9: 25952 | Q9: 26606 | R9: 25587 | S9: 27079 | T9: 28327 | U9: 29221 | V9: 29948 | W9: 30289.602 | X9: =W9*(1+$X$20) -> 30919.591 | Y9: =X9*(1+$Y$20) -> 31659.938 | Z9: =Y9*(1+$Z$20) -> 32368.221 | AA9: =Z9*(1+$AA$20) -> 33117.801 | AB9: =AA9*(1+$AB$20) -> 33871.72
A10: F | B10: Construcción | C10: 29808 | D10: 33427 | E10: 35747 | F10: 39289 | G10: 40316 | H10: 40048 | I10: 42536 | J10: 45051 | K10: 50131 | L10: 54602 | M10: 58042 | N10: 60125 | O10: 58907 | P10: 58156 | Q10: 55893 | R10: 39359 | S10: 41039 | T10: 43765 | U10: 42412 | V10: 42448 | W10: 41273.053 | X10: =W10*(1+$X$20) -> 42131.485 | Y10: =X10*(1+$Y$20) -> 43140.293 | Z10: =Y10*(1+$Z$20) -> 44105.408 | AA10: =Z10*(1+$AA$20) -> 45126.798 | AB10: =AA10*(1+$AB$20) -> 46154.098
A11: G + H + I | B11: Comercio al por mayor y al por menor; reparación de vehículos automotores y motocicletas; Transporte y almacenamiento; Alojamiento y servicios de comida | C11: 85427 | D11: 91926 | E11: 99343 | F11: 102346 | G11: 102185 | H11: 107647 | I11: 115063 | J11: 119453 | K11: 125149 | L11: 131063 | M11: 135429 | N11: 139066 | O11: 141652 | P11: 145438 | Q11: 150890 | R11: 130235 | S11: 156815 | T11: 175451 | U11: 169067 | V11: 171151 | W11: 179021.78 | X11: =W11*(1+$X$20) -> 182745.22 | Y11: =X11*(1+$Y$20) -> 187120.93 | Z11: =Y11*(1+$Z$20) -> 191307.11 | AA11: =Z11*(1+$AA$20) -> 195737.39 | AB11: =AA11*(1+$AB$20) -> 200193.3
A12: J | B12: Información y comunicaciones | C12: 12730 | D12: 14629 | E12: 16761 | F12: 17120 | G12: 15669 | H12: 18256 | I12: 20153 | J12: 20415 | K12: 22218 | L12: 23654 | M12: 23961 | N12: 23804 | O12: 23758 | P12: 24595 | Q12: 24821 | R12: 24133 | S12: 27210 | T12: 30564 | U12: 31034 | V12: 30969 | W12: 31269.035 | X12: =W12*(1+$X$20) -> 31919.395 | Y12: =X12*(1+$Y$20) -> 32683.682 | Z12: =Y12*(1+$Z$20) -> 33414.867 | AA12: =Z12*(1+$AA$20) -> 34188.686 | AB12: =AA12*(1+$AB$20) -> 34966.982
A13: K | B13: Actividades financieras y de seguros | C13: 15424 | D13: 16440 | E13: 18702 | F13: 20598 | G13: 21315 | H13: 22312 | I13: 24754 | J13: 26626 | K13: 29160 | L13: 32139 | M13: 34696 | N13: 35726 | O13: 37651 | P13: 39057 | Q13: 41505 | R13: 42433 | S13: 44003 | T13: 46940 | U13: 51135 | V13: 51684 | W13: 53112.342 | X13: =W13*(1+$X$20) -> 54217.017 | Y13: =X13*(1+$Y$20) -> 55515.204 | Z13: =Y13*(1+$Z$20) -> 56757.166 | AA13: =Z13*(1+$AA$20) -> 58071.544 | AB13: =AA13*(1+$AB$20) -> 59393.528
A14: L | B14: Actividades inmobiliarias | C14: 50233 | D14: 52265 | E14: 54225 | F14: 55731 | G14: 57866 | H14: 59932 | I14: 61628 | J14: 63579 | K14: 65625 | L14: 67664 | M14: 69825 | N14: 72289 | O14: 74495 | P14: 77449 | Q14: 79964 | R14: 81118 | S14: 83143 | T14: 84843 | U14: 86413 | V14: 88322 | W14: 90073.805 | X14: =W14*(1+$X$20) -> 91947.235 | Y14: =X14*(1+$Y$20) -> 94148.846 | Z14: =Y14*(1+$Z$20) -> 96255.103 | AA14: =Z14*(1+$AA$20) -> 98484.171 | AB14: =AA14*(1+$AB$20) -> 100726.14
A15: M + N | B15: Actividades profesionales, científicas y técnicas; Actividades de servicios administrativos y de apoyo | C15: 36057 | D15: 38592 | E15: 41246 | F15: 42800 | G15: 43998 | H15: 45354 | I15: 48568 | J15: 50907 | K15: 53593 | L15: 57500 | M15: 57392 | N15: 55995 | O15: 56810 | P15: 59066 | Q15: 61102 | R15: 57564 | S15: 63167 | T15: 68132 | U15: 69437 | V15: 69146 | W15: 70073.646 | X15: =W15*(1+$X$20) -> 71531.096 | Y15: =X15*(1+$Y$20) -> 73243.857 | Z15: =Y15*(1+$Z$20) -> 74882.436 | AA15: =Z15*(1+$AA$20) -> 76616.558 | AB15: =AA15*(1+$AB$20) -> 78360.714
A16: O + P + Q | B16: Administración pública y defensa; planes de seguridad social de afiliación obligatoria; Educación; Actividades de atención de la salud humana y de servicios sociales | C16: 71182 | D16: 74469 | E16: 77514 | F16: 79167 | G16: 81581 | H16: 85362 | I16: 90265 | J16: 95283 | K16: 100531 | L16: 106408 | M16: 112077 | N16: 116198 | O16: 120222 | P16: 125916 | Q16: 132333 | R16: 132742 | S16: 143974 | T16: 145589 | U16: 152772 | V16: 158980 | W16: 166116.4 | X16: =W16*(1+$X$20) -> 169571.42 | Y16: =X16*(1+$Y$20) -> 173631.69 | Z16: =Y16*(1+$Z$20) -> 177516.1 | AA16: =Z16*(1+$AA$20) -> 181627.01 | AB16: =AA16*(1+$AB$20) -> 185761.7
A17: R + S + T | B17: Actividades artísticas, de entretenimiento y recreación y otras actividades de servicios; Actividades de los hogares individuales en calidad de empleadores; actividades no diferenciadas de los hogares individuales como productores de bienes y servicios para uso propio | C17: 12776 | D17: 13424 | E17: 14135 | F17: 14558 | G17: 14897 | H17: 15259 | I17: 16188 | J17: 16677 | K17: 17718 | L17: 18210 | M17: 18982 | N17: 20034 | O17: 20456 | P17: 20925 | Q17: 23653 | R17: 20865 | S17: 28048 | T17: 35932 | U17: 39661 | V17: 42910 | W17: 47155.337 | X17: =W17*(1+$X$20) -> 48136.113 | Y17: =X17*(1+$Y$20) -> 49288.698 | Z17: =Y17*(1+$Z$20) -> 50391.363 | AA17: =Z17*(1+$AA$20) -> 51558.323 | AB17: =AA17*(1+$AB$20) -> 52732.035
B18: Impuestos menos subvenciones sobre los productos | C18: 42525 | D18: 47627 | E18: 52813 | F18: 55501 | G18: 54615 | H18: 58006 | I18: 64001 | J18: 66873 | K18: 69095 | L18: 72899 | M18: 74149 | N18: 74955 | O18: 75773 | P18: 78088 | Q18: 81489 | R18: 76490 | S18: 88640 | T18: 102860 | U18: 100274 | V18: 100775 | W18: 103267.18 | X18: =W18*(1+$X$20) -> 105415.02 | Y18: =X18*(1+$Y$20) -> 107939.11 | Z18: =Y18*(1+$Z$20) -> 110353.87 | AA18: =Z18*(1+$AA$20) -> 112909.44 | AB18: =AA18*(1+$AB$20) -> 115479.79
B19: PIB | C19: =SUM(C6:C18) -> 517438 | D19: =SUM(D6:D18) -> 552139 | E19: =SUM(E6:E18) -> 588990 | F19: =SUM(F6:F18) -> 608384 | G19: =SUM(G6:G18) -> 614390 | H19: =SUM(H6:H18) -> 640461 | I19: =SUM(I6:I18) -> 683340 | J19: =SUM(J6:J18) -> 709685 | ... AB19: =SUM(AB6:AB18) -> 1144502.4
B20: Tasas de Crecimiento | C20: 0 | D20: =IFERROR((D$19/C$19)-1,"") -> 0.067063107 | E20: =IFERROR((E$19/D$19)-1,"") -> 0.066742251 | F20: =IFERROR((F$19/E$19)-1,"") -> 0.032927554 | G20: =IFERROR((G$19/F$19)-1,"") -> 0.0098720545 | H20: =IFERROR((H$19/G$19)-1,"") -> 0.042433959 | I20: =IFERROR((I$19/H$19)-1,"") -> 0.066950212 | J20: =IFERROR((J$19/I$19)-1,"") -> 0.038553282 | K20: =IFERROR((K$19/J$19)-1,"") -> 0.051001501 | ... W20: =IFERROR((W$19/V$19)-1,"") -> 0.027089735 | X20: =AVERAGE(V20:W20) -> 0.020798836 | Y20: =AVERAGE(W20:X20) -> 0.023944285 | Z20: =AVERAGE(X20:Y20) -> 0.02237156 | AA20: =AVERAGE(Y20:Z20) -> 0.023157923 | AB20: =AVERAGE(Z20:AA20) -> 0.022764742
X21: Tasa de crecimiento Inercial

Sheet C1G
A3: Producto Interno Bruto (PIB)
A5: Series encadenadas de volumen con año de referencia 2015 | I5: Índice
A6: Datos originales | I6: Tasa de crecimiento anual
A7: Miles de millones de pesos | I7: Tasa de crecimiento año corrido
A8: 2005 - 2025pr cuarto trimestre
A10: Clasificación Cuentas Nacionales | B10: Concepto | C10: 2005 | G10: 2006 | K10: 2007 | O10: 2008 | S10: 2009 | W10: 2010 | AA10: 2011 | AE10: 2012 | AI10: 2013 | AM10: 2014 | AQ10: 2015 | AU10: 2016 | AY10: 2017 | BC10: 2018 | BG10: 2019 | BK10: 2020 | BO10: 2021 | BS10: 2022 | BW10: 2023 | CA10: 2024p | CE10: 2025pr
C11: I | D11: II | E11: III | F11: IV | G11: I | H11: II | I11: III | J11: IV | K11: I | L11: II | M11: III | N11: IV | O11: I | P11: II | Q11: III | R11: IV | S11: I | T11: II | U11: III | V11: IV | W11: I | X11: II | Y11: III | Z11: IV | AA11: I | AB11: II | AC11: III | AD11: IV | AE11: I | AF11: II | AG11: III | AH11: IV | AI11: I | AJ11: II | AK11: III | AL11: IV | AM11: I | AN11: II | AO11: III | AP11: IV | AQ11: I | AR11: II | AS11: III | AT11: IV | AU11: I | AV11: II | AW11: III | AX11: IV | AY11: I | AZ11: II | BA11: III | BB11: IV | BC11: I | BD11: II | BE11: III | BF11: IV | BG11: I | BH11: II | BI11: III | BJ11: IV | BK11: I | BL11: II | BM11: III | BN11: IV | BO11: I | BP11: II | BQ11: III | BR11: IV | BS11: I | BT11: II | BU11: III | BV11: IV | BW11: I | BX11: II | BY11: III | BZ11: IV | CA11: I | CB11: II | CC11: III | CD11: IV | CE11: I | CF11: II | CG11: III | CH11: IV
A13: P.8 | B13: Demanda interna1 | C13: 113928.9 | D13: 124084.41 | E13: 123351.17 | F13: 140033.52 | G13: 123815.12 | H13: 133231.53 | I13: 137786.66 | J13: 148804.68 | K13: 135409.59 | L13: 144784.42 | M13: 148604.92 | N13: 160090.07 | O13: 143788.11 | P13: 151865.49 | Q13: 156129.81 | R13: 168374.59 | S13: 145532.07 | T13: 153254.65 | U13: 154800.28 | V13: 168146 | W13: 151170.84 | X13: 162607.5 | Y13: 164875.49 | Z13: 180663.16 | AA13: 163099.4 | AB13: 176876.06 | AC13: 180404.74 | AD13: 194565.81 | AE13: 174812.47 | AF13: 188008.54 | AG13: 186033.64 | AH13: 201113.36 | AI13: 182393.4 | AJ13: 198564.87 | AK13: 200275.98 | AL13: 212902.74 | AM13: 195439.59 | AN13: 209079.4 | AO13: 209503.61 | AP13: 227658.4 | AQ13: 201365.26 | AR13: 212547.9 | AS13: 219441.82 | AT13: 228151.03 | AU13: 208074.34 | AV13: 213949.74 | AW13: 220373.31 | AX13: 229697.61 | AY13: 210291.93 | AZ13: 216680.18 | BA13: 223348.94 | BB13: 231576.96 | BC13: 213668.72 | BD13: 224260.03 | BE13: 231147.03 | BF13: 243365.22 | BG13: 223423.4 | BH13: 232655.89 | BI13: 242127.15 | BJ13: 250928.56 | BK13: 224619.24 | BL13: 190733.14 | BM13: 218543.84 | BN13: 243663.78 | BO13: 228863.05 | BP13: 236559.49 | BQ13: 254910.16 | BR13: 274583.3 | BS13: 258686.31 | BT13: 269145.74 | BU13: 280995.58 | BV13: 288085.36 | BW13: 262714.59 | BX13: 263719.92 | BY13: 265792.62 | BZ13: 278252.87 | CA13: 256425.61 | CB13: 267570.98 | CC13: 275251.02 | CD13: 288475.39 | CE13: 267840.88 | CF13: 278212.21 | CG13: 288773.29 | CH13: 295185.3
A14: P.3 | B14: Gasto de consumo final | C14: 96825.974 | D14: 100409.3 | E14: 102609.15 | F14: 119232.57 | G14: 102452.09 | H14: 106038.66 | I14: 109477.96 | J14: 126974.3 | K14: 108438.93 | L14: 111779.6 | M14: 116912.99 | N14: 135459.48 | O14: 114402.92 | P14: 116980.11 | Q14: 120931.49 | R14: 140192.48 | S14: 117214.41 | T14: 120058.62 | U14: 123358.45 | V14: 142784.52 | W14: 121815.43 | X14: 125685.49 | Y14: 130093.91 | Z14: 151407.16 | AA14: 127449.68 | AB14: 133770.09 | AC14: 137251.26 | AD14: 160521.97 | AE14: 136261.94 | AF14: 140708.43 | AG14: 144495.54 | AH14: 168228.09 | AI14: 142835.11 | AJ14: 149048.09 | AK14: 151944.03 | AL14: 177438.78 | AM14: 149686.07 | AN14: 154955.27 | AO14: 158197.49 | AP14: 185295.17 | AQ14: 155721.43 | AR14: 161711.33 | AS14: 166725.69 | AT14: 186042.55 | AU14: 158563.97 | AV14: 164095.96 | AW14: 166939.36 | AX14: 191501.71 | AY14: 160470.84 | AZ14: 168618.97 | BA14: 171932.09 | BB14: 195951.09 | BC14: 166269.07 | BD14: 175723.43 | BE14: 178796 | BF14: 203859.5 | BG14: 171813.54 | BH14: 183080.61 | BI14: 186937.14 | BJ14: 213924.71 | BK14: 178492.74 | BL14: 156964.65 | BM14: 172968.74 | BN14: 215481.87 | BO14: 184383.5 | BP14: 191510.34 | BQ14: 205151.35 | BR14: 242517.82 | BS14: 206010.52 | BT14: 221009.29 | BU14: 222958.16 | BV14: 247849.02 | BW14: 210298.41 | BX14: 222116.95 | BY14: 223416.64 | BZ14: 248089.99 | CA14: 210280.22 | CB14: 225183.15 | CC14: 224980.36 | CD14: 256724.26 | CE14: 218025.52 | CF14: 233652.07 | CG14: 237786.53 | CH14: 266461.13
A15: P.311 + P.313 + P.323 | B15: Gasto de consumo final individual de los hogares; gasto de consumo final de las ISFLH2 | C15: 82036.688 | D15: 84948.292 | E15: 86762.234 | F15: 94993.786 | G15: 86994.134 | H15: 90321.977 | I15: 92815.415 | J15: 100821.47 | K15: 92916.648 | L15: 95726.891 | M15: 99222.679 | N15: 107394.78 | O15: 97989.473 | P15: 99424.301 | Q15: 102764.67 | R15: 111347.55 | S15: 100026.39 | T15: 101870.58 | U15: 104015.22 | V15: 112643.8 | W15: 103799.36 | X15: 106508.91 | Y15: 109969.21 | Z15: 119426.52 | AA15: 108556.1 | AB15: 113235.78 | AC15: 115730.8 | AD15: 126368.32 | AE15: 116518.98 | AF15: 119286.48 | AG15: 122173.08 | AH15: 132047.45 | AI15: 121787.04 | AJ15: 125697.13 | AK15: 127427.94 | AL15: 137786.9 | AM15: 126810.99 | AN15: 130399.77 | AO15: 132771.01 | AP15: 144502.22 | AQ15: 131345.74 | AR15: 134566.1 | AS15: 137911.62 | AT15: 147189.54 | AU15: 134710.34 | AV15: 136275.33 | AW15: 138980.61 | AX15: 149772.72 | AY15: 135913.58 | AZ15: 139850.77 | BA15: 142791.44 | BB15: 152679.21 | BC15: 140483.36 | BD15: 144733.83 | BE15: 147349.31 | BF15: 157156.5 | BG15: 144587.36 | BH15: 149984.36 | BI15: 153725.84 | BJ15: 165430.45 | BK15: 151599.84 | BL15: 124339.01 | BM15: 140331.21 | BN15: 166726.94 | BO15: 154416.8 | BP15: 155973.11 | BQ15: 168170.24 | BR15: 190277.85 | BS15: 173355.6 | BT15: 181882.03 | BU15: 186525.82 | BV15: 199240.55 | BW15: 178431.02 | BX15: 183252.67 | BY15: 185662.96 | BZ15: 197460.35 | CA15: 179189.63 | CB15: 185291.26 | CC15: 189261.59 | CD15: 203280.52 | CE15: 185961.23 | CF15: 192014.7 | CG15: 196975.68 | CH15: 209564.53
A16: P.312 + P.322 | B16: Gasto de consumo final del gobierno general | C16: 14794.446 | D16: 15480.993 | E16: 15874.025 | F16: 24225.536 | G16: 15466.853 | H16: 15749.044 | I16: 16695.887 | J16: 26132.216 | K16: 15579.35 | L16: 16128.584 | M16: 17750.039 | N16: 27969.027 | O16: 16500.732 | P16: 17630.863 | Q16: 18252.41 | R16: 28679.995 | S16: 17189.977 | T16: 18204.911 | U16: 19363.433 | V16: 30166.679 | W16: 18048.824 | X16: 19218.287 | Y16: 20171.206 | Z16: 31924.683 | AA16: 18936.727 | AB16: 20583.608 | AC16: 21569.322 | AD16: 34061.343 | AE16: 19737.409 | AF16: 21432.211 | AG16: 22341.318 | AH16: 36214.062 | AI16: 21042.75 | AJ16: 23358.572 | AK16: 24528.877 | AL16: 39665.802 | AM16: 22883.845 | AN16: 24577.397 | AO16: 25455.194 | AP16: 40757.564 | AQ16: 24375.409 | AR16: 27145.2 | AS16: 28814.184 | AT16: 38853.207 | AU16: 23853.738 | AV16: 27820.673 | AW16: 27958.724 | AX16: 41728.865 | AY16: 24437.118 | AZ16: 28730 | BA16: 29095.947 | BB16: 43519.935 | BC16: 25738.385 | BD16: 30991.208 | BE16: 31447.17 | BF16: 46853.237 | BG16: 27196.72 | BH16: 33111.357 | BI16: 33220.085 | BJ16: 48623.839 | BK16: 26866.683 | BL16: 32677.636 | BM16: 32667.172 | BN16: 48859.51 | BO16: 30023.147 | BP16: 35584.196 | BQ16: 37034.31 | BR16: 52280.347 | BS16: 32405.161 | BT16: 39061.836 | BU16: 36216.021 | BV16: 48768.982 | BW16: 31239.05 | BX16: 38779.958 | BY16: 37519.966 | BZ16: 51339.027 | CA16: 30609.064 | CB16: 39851.134 | CC16: 35380.284 | CD16: 53970.518 | CE16: 31764.184 | CF16: 41583.14 | CG16: 40698.212 | CH16: 57180.695
A17: P.5 | B17: Formación bruta de capital | C17: 18548.464 | D17: 23912.502 | E17: 21772.334 | F17: 22486.7 | G17: 22240.984 | H17: 27234.14 | I17: 28214.251 | J17: 23715.625 | K17: 27087.063 | L17: 32620.846 | M17: 31425.569 | N17: 26290.522 | O17: 29447.374 | P17: 34605.521 | Q17: 34765.616 | R17: 29271.489 | S17: 28674.734 | T17: 33083.151 | U17: 31663.907 | V17: 26604.208 | W17: 29710.029 | X17: 36649.584 | Y17: 34768.272 | Z17: 30375.114 | AA17: 35503.928 | AB17: 42885.838 | AC17: 42623.777 | AD17: 34838.458 | AE17: 38420.059 | AF17: 47146.296 | AG17: 41460.761 | AH17: 33323.885 | AI17: 39587.915 | AJ17: 49537.532 | AK17: 48137.977 | AL17: 35605.576 | AM17: 45621.399 | AN17: 54366.003 | AO17: 51206.561 | AP17: 42339.038 | AQ17: 45629.521 | AR17: 50836.472 | AS17: 52724.857 | AT17: 42114.15 | AU17: 49513.564 | AV17: 49853.542 | AW17: 53431.836 | AX17: 38195.057 | AY17: 49865.417 | AZ17: 48068.737 | BA17: 51447.385 | BB17: 35446.461 | BC17: 47438.283 | BD17: 48548 | BE17: 52418.147 | BF17: 39203.571 | BG17: 51679.275 | BH17: 49562.686 | BI17: 55250.433 | BJ17: 36654.606 | BK17: 46075.354 | BL17: 33674.439 | BM17: 45531.961 | BN17: 27921.247 | BO17: 44240.555 | BP17: 44827.742 | BQ17: 49486.589 | BR17: 32368.114 | BS17: 52350.015 | BT17: 47973.173 | BU17: 57661.907 | BV17: 40358.904 | BW17: 52140.524 | BX17: 41553.742 | BY17: 42317.116 | BZ17: 30394.619 | CA17: 46049.785 | CB17: 42342.659 | CC17: 50160.977 | CD17: 31834.579 | CE17: 49687.499 | CF17: 44507.053 | CG17: 50879.048 | CH17: 28873.792
A18: P.51 | B18: Formación bruta de capital fijo | C18: 18507.162 | D18: 19918.576 | E18: 20553.359 | F18: 26958.903 | G18: 20661.048 | H18: 22856.2 | I18: 25926.201 | J18: 32626.551 | K18: 26638.797 | L18: 29355.031 | M18: 30867.009 | N18: 35512.163 | O18: 24056.647 | P18: 30171.637 | Q18: 30064.236 | R18: 34757.479 | S18: 25752.829 | T18: 30823.172 | U18: 32017.247 | V18: 35760.753 | W18: 25624.208 | X18: 33920.148 | Y18: 33380.259 | Z18: 40264.385 | AA18: 30263.715 | AB18: 36864.724 | AC18: 38555.824 | AD18: 43769.736 | AE18: 31661.212 | AF18: 39745.52 | AG18: 39330.248 | AH18: 43700.021 | AI18: 34741.942 | AJ18: 42393.653 | AK18: 40952.69 | AL18: 49444.714 | AM18: 38898.453 | AN18: 45795.094 | AO18: 46745.951 | AP18: 51517.502 | AQ18: 40790.507 | AR18: 48657.84 | AS18: 48478.49 | AT18: 50168.163 | AU18: 38485.368 | AV18: 47214.044 | AW18: 45284.074 | AX18: 51675.514 | AY18: 40404.479 | AZ18: 46582.572 | BA18: 47629.636 | BB18: 51429.313 | BC18: 39327.69 | BD18: 48458.461 | BE18: 48181.442 | BF18: 52007.407 | BG18: 44526.5 | BH18: 48942.697 | BI18: 48913.69 | BJ18: 49796.113 | BK18: 39636.464 | BL18: 27744.586 | BM18: 36407.213 | BN18: 42994.736 | BO18: 41623.676 | BP18: 39400.705 | BQ18: 41644.304 | BR18: 48621.315 | BS18: 47206.035 | BT18: 43656.038 | BU18: 47315.684 | BV18: 52807.242 | BW18: 44783.552 | BX18: 38053.901 | BY18: 39822.548 | BZ18: 43847.999 | CA18: 40362.981 | CB18: 38158.957 | CC18: 40774.236 | CD18: 48326.826 | CE18: 41144.243 | CF18: 38968.158 | CG18: 42833.056 | CH18: 46919.348
A19: P.6 | B19: Exportaciones | C19: 19831.478 | D19: 22333.865 | E19: 22882.818 | F19: 23076.84 | G19: 22337.196 | H19: 23616.113 | I19: 24648.785 | J19: 25910.905 | K19: 22749.44 | L19: 23879.216 | M19: 26699.485 | N19: 29187.86 | O19: 25886.593 | P19: 26784.471 | Q19: 26681.821 | R19: 25251.115 | S19: 24406.005 | T19: 24028.165 | U19: 24749.954 | V19: 25973.876 | W19: 24198.079 | X19: 25176.646 | Y19: 25210.557 | Z19: 26617.718 | AA19: 27426.425 | AB19: 28064.061 | AC19: 28190.065 | AD19: 29927.449 | AE19: 29769.725 | AF19: 28695.08 | AG19: 30038.437 | AH19: 30186.758 | AI19: 28895.47 | AJ19: 31197.575 | AK19: 30326.538 | AL19: 33821.416 | AM19: 30502.45 | AN19: 30298.846 | AO19: 31231.104 | AP19: 31849.6 | AQ19: 30585.323 | AR19: 32190.708 | AS19: 30319.263 | AT19: 32840.706 | AU19: 30067.975 | AV19: 30729.535 | AW19: 30634.088 | AX19: 34241.402 | AY19: 31008.905 | AZ19: 31689.325 | BA19: 31797.103 | BB19: 34406.667 | BC19: 30290.307 | BD19: 31637.21 | BE19: 32292.94 | BF19: 35509.543 | BG19: 32383.564 | BH19: 33754.201 | BI19: 33131.091 | BJ19: 34462.144 | BK19: 30089.282 | BL19: 23187.731 | BM19: 23824.354 | BN19: 26594.633 | BO19: 27041.913 | BP19: 26412.121 | BQ19: 30083.477 | BR19: 35333.488 | BS19: 31642.301 | BT19: 32988.543 | BU19: 34299.016 | BV19: 34753.141 | BW19: 32665.65 | BX19: 33508.39 | BY19: 34444.178 | BZ19: 37226.782 | CA19: 32589.737 | CB19: 33628.265 | CC19: 34113.571 | CD19: 38051.428 | CE19: 33651.524 | CF19: 33750.621 | CG19: 35035.367 | CH19: 38496.496
A20: P.7 | B20: Importaciones | C20: 17191.887 | D20: 19339.358 | E20: 20415.212 | F20: 21761.544 | G20: 19843.498 | H20: 22699.553 | I20: 24811.224 | J20: 25270.724 | K20: 22971.884 | L20: 25138.541 | M20: 27951.173 | N20: 29399.401 | O20: 26870.347 | P20: 27925.185 | Q20: 30610.74 | R20: 33249.728 | S20: 26942.143 | T20: 25672.504 | U20: 26739.45 | V20: 29040.903 | W20: 26872.721 | X20: 29019.313 | Y20: 30983.896 | Z20: 33258.07 | AA20: 32036.199 | AB20: 35552.833 | AC20: 37143.518 | AD20: 39703.45 | AE20: 36718.513 | AF20: 38996.592 | AG20: 40953.576 | AH20: 41308.319 | AI20: 39193.371 | AJ20: 42788.537 | AK20: 44415.28 | AL20: 45045.813 | AM20: 42509.443 | AN20: 45820.852 | AO20: 46418.099 | AP20: 49998.607 | AQ20: 43154.379 | AR20: 44377.699 | AS20: 48338.023 | AT20: 46879.898 | AU20: 42232.184 | AV20: 43640.088 | AW20: 44202.933 | AX20: 46203.795 | AY20: 43270.781 | AZ20: 44758.819 | BA20: 44860.126 | BB20: 45185.274 | BC20: 42666.012 | BD20: 46805.548 | BE20: 47121.114 | BF20: 51820.326 | BG20: 47737.017 | BH20: 51081.703 | BI20: 52287.79 | BJ20: 51143.49 | BK20: 45676.655 | BL20: 33917.385 | BM20: 38904.962 | BN20: 43113.998 | BO20: 43287.183 | BP20: 49494.877 | BQ20: 54303.199 | BR20: 57724.741 | BS20: 60097.176 | BT20: 62196.963 | BU20: 67259.286 | BV20: 64417.575 | BW20: 59110.861 | BX20: 57214.09 | BY20: 54913.957 | BZ20: 57259.092 | CA20: 52552.516 | CB20: 57422.494 | CC20: 59552.081 | CD20: 61629.909 | CE20: 59221.745 | CF20: 63408.013 | CG20: 65475.264 | CH20: 62513.81
A21: B.1b | B21: Producto Interno Bruto | C21: 121117.73 | D21: 125559.34 | E21: 129223.31 | F21: 138952.62 | G21: 128839.68 | H21: 132242.91 | I21: 139114.41 | J21: 149238 | K21: 137488.52 | L21: 141316.5 | M21: 148649.97 | N21: 159002.02 | O21: 144602.69 | P21: 148078.93 | Q21: 153584.53 | R21: 159446.84 | S21: 144812.49 | T21: 149108.6 | U21: 154402.16 | V21: 164292.74 | W21: 150431.72 | X21: 156004.2 | Y21: 160651.52 | Z21: 173063.55 | AA21: 160659.88 | AB21: 166585.33 | AC21: 173372.36 | AD21: 184010.44 | AE21: 170516.61 | AF21: 174658.12 | AG21: 177268.45 | AH21: 188971.82 | AI21: 174578.04 | AJ21: 184043.02 | AK21: 188345.14 | AL21: 200972.79 | AM21: 186100.22 | AN21: 190347.09 | AO21: 196605.87 | AP21: 208535.82 | AQ21: 191363.28 | AR21: 196861.4 | AS21: 203635.77 | AT21: 212831.55 | AU21: 195907.74 | AV21: 201038.99 | AW21: 206805.58 | AX21: 217736.68 | AY21: 198002.9 | AZ21: 203591.84 | BA21: 210300.68 | BB21: 220760.57 | BC21: 201268.45 | BD21: 209187.55 | BE21: 216359.03 | BF21: 227192.98 | BG21: 208263.59 | BH21: 215620.27 | BI21: 223124.46 | BJ21: 234215.69 | BK21: 208984.37 | BL21: 179587.95 | BM21: 202864.17 | BN21: 226463.51 | BO21: 212118.51 | BP21: 212672.15 | BQ21: 229893.55 | BR21: 251558.79 | BS21: 229311 | BT21: 239013.85 | BU21: 246908.06 | BV21: 257422.1 | BW21: 235748.94 | BX21: 239983.68 | BY21: 245804.91 | BZ21: 259305.47 | CA21: 236500.46 | CB21: 243822.84 | CC21: 249751.85 | CD21: 265414.85 | CE21: 242632.98 | CF21: 248985.66 | CG21: 258737.57 | CH21: 271434.71
A23: Fuente: DANE, PIB_T
